Workbook

Sheet Interfaz
E7: D Actual
E9: d actual | F9: 1.01
E11: Bodegas | F11: F/Slc | G11: D/V/% | J11: Fe/d | M11: D Tm ACT
E12: B1 | F12: Vacio | M12: {='D Actual'!N8:N12} -> 0
E13: B2 | F13: Vacio | M13: 0
E14: B3 | F14: Vacio | M14: 0
E15: B4 | F15: Vacio | M15: 0
E16: B5 | F16: Vacio | M16: 0
E19: Heavy Fuel Oil | F19: F/Slc | G19: % | H19: d | I19: 0.95 | J19: Tm | K19: m3 | L19: D Tm ACT
E20: HFO Deep P 1 | F20: Full | H20: Igual | L20: {='D Actual'!N16:N24} -> 412.205
E21: HFO Deep S 1 | F21: Full | H21: Igual | L21: 326.23
E22: HFO Deep P 2 | F22: Slack | G22: 70 | H22: Igual | L22: 354.578
E23: HFO Deep S 2 | L23: 0
E24: HFO Service Tk 1 | F24: Full | H24: Igual | L24: 42.94
E25: HFO Service Tk 2 | L25: 0
E26: HFO Settling Tk 1 | F26: Full | H26: Igual | L26: 42.94
E27: HFO Settling Tk 2 | F27: Slack | G27: 20 | H27: Igual | L27: 8.588
E28: HFO Overflow Tk | F28: Slack | G28: 12 | H28: Igual | L28: 4.389
E31: Diesel Oil | F31: F/Slc | G31: % | H31: d | I31: 0.85 | J31: Tm | K31: m3 | L31: D Tm ACT
E32: DO Deep Tk S | L32: {='D Actual'!N28:N31} -> 0
E33: DO Service Tk 1 | F33: Slack | G33: 80 | H33: Igual | L33: 15.368
E34: DO Service Tk 2 | L34: 0
E35: DO Settling Tk | F35: Slack | G35: 18 | H35: Igual | L35: 3.4578
E38: Water Ballast | F38: F/Slc | G38: % | H38: d | I38: 1.025 | J38: Tm | K38: m3 | L38: D Tm ACT
E39: Fore Peak tank | F39: Full | H39: Igual | L39: {='D Actual'!Y8:Y32} -> 1921.1575
E40: DB Ballast P 1 | F40: Full | H40: Igual | L40: 251.6375
E41: DB Ballast S 1 | F41: Full | H41: Igual | L41: 251.6375
E42: WT Ballast P 1 | F42: Full | H42: Igual | L42: 1093.5725
E43: WT Ballast S 1 | F43: Full | H43: Igual | L43: 1093.5725
E44: DB Ballast P 2 | F44: Full | H44: Igual | L44: 622.8925
E45: DB Ballast S 2 | F45: Full | H45: Igual | L45: 622.8925
E46: WT Ballast P 2 | F46: Full | H46: Igual | L46: 1033.7125
E47: WT Ballast S 2 | F47: Full | H47: Igual | L47: 1033.7125
E48: DB Ballast P 3 | F48: Full | H48: Igual | L48: 622.8925
E49: DB Ballast S 3 | F49: Full | H49: Igual | L49: 622.8925
E50: WT Ballast P 3 | F50: Full | H50: Igual | L50: 1035.045
E51: WT Ballast S 3 | F51: Full | H51: Igual | L51: 1035.045
... E53: DB Ballast S 4 | F53: Full | H53: Igual | L53: 622.8925
E54: WT Ballast P 4 | L54: 0
E55: WT Ballast S 4 | F55: Slack | G55: 21 | H55: Igual | L55: 214.84103
...

Sheet Leyenda
K6: Navegación:
K7: V media (Kt) | L7: Velocidad | O7: Consumos: | R7: D Máximos: | U7: Calados Act Sal Lleg | X7: Análisis Inundación: | AC7: Orden recomendado:
K8: D RL | L8: Distancia | O8: CMOxd | P8: Consumo por día | R8: CH | S8: Calado Hidroestático | U8: A | V8: Asiento | X8: Despla. | Y8: Desplazamiento | AC8: D Actual | AD8: Distribución Original de pesos
K9: T RL (días) | L9: Tiempo | O9: HFO | P9: Heavy Fuel Oil | R9: sw | S9: Agua salada | U9: Cpp | V9: Calado de Popa | X9: Inund. | Y9: Inundación | AC9: Condición Actual | AD9: Estado del buque inicial
K10: Derr. Elegida: | L10: Derrota | O10: dmax | P10: Días máximos | R10: bw | S10: Agua salobre | U10: Arruf | V10: Arrufo | X10: Inun. | Y10: Inundación | AC10: Navegación | AD10: Planificación de la derrota (Puerto de origen y velocidad)
K11: RL | L11: Loxodromica | O11: Cap | P11: Capacidad | R11: fw | S11: Agua dulce | U11: Quebr | V11: Quebranto | X11: B.vcg | Y11: Bajar centro de gravedad | AC11: Consumos | AD11: Consumos diarios
F12: Título | G12: Títulos Sección | K12: GC | L12: Ortodrómica | O12: duso | P12: Días de uso | R12: corr x d | S12: Corregido por densidad | X12: Ltr.Es. | Y12: Lastrar a Estribor | AC12: Navegación | AD12: Planificación de la derrota (Puerto de destino y selección metodo de navegación)
F13: Texto | G13: Texto Entradas/Salidas/Constantes | K13: Limt | L13: Límite | O13: CMOtot | P13: Consumo total | X13: Trsgo. | Y13: Trasiego | AC13: D Máximos | AD13: Datos puerto de Salida y de Llegada y cambio de zona (Si aplica)
F14: Entrada | G14: Celda de Entrada de datos | O14: dRest | P14: Días restantes | U14: Carga y Reparto: | X14: Trsgo.F. | Y14: Trasiego Final | AC14: Carga Y Reparto | AD14: Carga
F15: Salida | G15: Celda de Salida de datos | O15: LLEG | P15: Llegada | R15: Condición X: | U15: %ACT | V15: Porcentaje de llenado Actual | AC15: Consumos | AD15: Distribución consumos
F16: Selección | G16: Celda de selección | K16: D Actual: | L16: Desplazamiento Actual | O16: DO | P16: Diesel Oil | R16: C | S16: Calado | U16: Mx | V16: Máximo | AC16: Carga Y Reparto | AD16: Reparto
G17: Celda Vacía | K17: F | L17: Full/Lleno | O17: LO | P17: Lube Oil | R17: CM | S17: Calado en la Marca | AC17: Condición Salida | AD17: Estado del buque a la Salida
K18: Slc | L18: Slack/Parcialmente Lleno | O18: Misc.Oil | P18: Miscellaneus Oil | R18: Cpp | S18: Calado en la Perpendicular | AC18: Condición Llegada | AD18: Estado del buque a la Llegada
K19: V | L19: Volumen | O19: Misc.Wt | P19: Miscellaneus Water | R19: Cx | S19: Calado en la Maestra
K20: % | L20: Porcentaje de llenado | O20: FW | P20: Agua Dulce
K21: Fe | L21: Factor de estiba
K22: d | L22: Densidad
K23: ACT | L23: Actual

Sheet TTHH
B8: Bodegas | C8: Vol 100% | D8: Vol 98% | E8: LCG | F8: TCG | G8: VCG | H8: FSM (m4) | J8: Eslora total | K8: 190 | Y8: Grain Shifting Moments B1 | AF8: Grain Shifting Moments B2 | AM8: Grain Shifting Moments B3 | AT8: Grain Shifting Moments B4 | BA8: Grain Shifting Moments B5 | BF8: Max. Grain Shifting Moments; TRIM = 0 | CL8: KN (m) TRIM = 0,0 m | CW8: KN (m) TRIM = 1,0 m
B9: B1 | C9: 12437.9 | D9: 12189.1 | E9: 158.6 | F9: 0 | G9: 10.12 | H9: 49541 | J9: Eslora entre PP | K9: 183.25 | M9: Freeboard | N9: Draft | O9: D | P9: DWT | S9: Calado en las marcas | W9: Height (m) | X9: Ullage (m) | Y9: V (m3) | Z9: VHM (m4) | AA9: LCG | AB9: VCG | AD9: Height (m) | AE9: Ullage (m) | AF9: V (m3) | AG9: VHM (m4) | AH9: LCG | AI9: VCG | AK9: Height (m) | AL9: Ullage (m) | AM9: V (m3) | AN9: VHM (m4) | AO9: LCG | AP9: VCG | AR9: Height (m) | AS9: Ullage (m) | AT9: V (m3) | AU9: VHM (m4) | AV9: LCG | AW9: VCG | AY9: Height (m) | AZ9: Ullage (m) | BA9: V (m3) | BB9: VHM (m4) | BC9: LCG | BD9: VCG | BF9: KG / Draft | BG9: 8 | BH9: 8.1 | BI9: 8.2 | BJ9: 8.3 | BK9: 8.4 | BL9: 8.5 | BM9: 8.6 | BN9: 8.7 | BO9: 8.8 | BP9: 8.9 | BQ9: 9 | BR9: 9.1 | BS9: 9.2 | BT9: 9.3 | BU9: 9.4 | BV9: 9.5 | BW9: 9.6 | BX9: 9.7 | BY9: 9.8 | BZ9: 9.9 | CA9: 10 | CB9: 10.1 | CC9: 10.2 | CD9: 10.3 | CE9: 10.4 | CF9: 10.5 | CG9: 10.6 | CH9: 10.7 | CI9: 10.8 | CJ9: 10.9 | CL9: Heeling angle / Draft | CM9: 5 | CN9: 10 | CO9: 12 | CP9: 20 | CQ9: 30 | CR9: 40 | CS9: 50 | CT9: 60 | CU9: 75 | CW9: Heeling angle / Draft | CX9: 5 | CY9: 10 | CZ9: 12 | DA9: 20 | DB9: 30 | DC9: 40 | DD9: 50 | DE9: 60 | DF9: 75
B10: B2 | C10: 13347 | D10: 13080 | E10: 130.02 | F10: 0 | G10: 10.21 | H10: 63136 | J10: Manga | K10: 32.26 | M10: TF | N10: 13.083 | O10: 66074 | P10: 55030 | R10: Cpp | S10: <11m | T10: >11m | W10: 17.775 | X10: 0 | Y10: 12431.5 | Z10: 536 | AA10: 158.59 | AB10: 10.12 | AD10: 17.975 | AE10: 0 | AF10: 13349.5 | AG10: 688 | AH10: 130.01 | AI10: 10.21 | AK10: 17.975 | AL10: 0 | AM10: 13351.3 | AN10: 688 | AO10: 101.22 | AP10: 10.21 | AR10: 17.975 | AS10: 0 | AT10: 13349.6 | AU10: 688 | AV10: 72.42 | AW10: 10.21 | AY10: 17.975 | AZ10: 0 | BA10: 13265.4 | BB10: 688 | BC10: 43.26 | BD10: 10.52 | BF10: 7.5 | BG10: 61272 | BH10: 60463 | BI10: 59654 | BJ10: 58845 | BK10: 58036 | BL10: 57227 | BM10: 56418 | BN10: 55609 | BO10: 54801 | BP10: 53992 | BQ10: 53182 | BR10: 52373 | BS10: 51565 | BT10: 50756 | BU10: 49947 | BV10: 49138 | BW10: 48329 | BX10: 47520 | BY10: 46711 | BZ10: 45902 | CA10: 45093 | CB10: 44284 | CC10: 43475 | CD10: 42667 | CE10: 41858 | CF10: 41049 | CG10: 40240 | CH10: 39431 | CI10: 38622 | CJ10: 37814 | CL10: 7.5 | CM10: 1.337 | CN10: 2.692 | CO10: 3.238 | CP10: 5.46 | CQ10: 8.176 | CR10: 10.143 | CS10: 11.165 | CT10: 11.662 | CU10: 11.419 | CW10: 7.5 | CX10: 1.348 | CY10: 2.713 | CZ10: 3.264 | DA10: 5.502 | DB10: 8.223 | DC10: 10.185 | DD10: 11.187 | DE10: 11.68 | DF10: 11.435
B11: B3 | C11: 13348.7 | D11: 13081.8 | E11: 101.22 | F11: 0 | G11: 10.21 | H11: 63150 | J11: Puntal | K11: 17.5 | M11: F | N11: 12.822 | O11: 64947 | P11: 53903 | R11: Esp K | S11: 0.022 | T11: 0.022 | W11: 17.575 | X11: 0.2 | Y11: 12351.7 | Z11: 1406 | AA11: 158.6 | AB11: 10.05 | AD11: 17.775 | AE11: 0.2 | AF11: 13253 | AG11: 1749 | AH11: 130.02 | AI11: 10.14 | AK11: 17.775 | AL11: 0.2 | AM11: 13254.8 | AN11: 1749 | AO11: 101.22 | AP11: 10.14 | AR11: 17.775 | AS11: 0.2 | AT11: 13253 | AU11: 1749 | AV11: 72.42 | AW11: 10.14 | AY11: 17.775 | AZ11: 0.2 | BA11: 13168.9 | BB11: 1749 | BC11: 43.26 | BD11: 10.46 | BF11: 7.6 | BG11: 61429 | BH11: 60609 | BI11: 59788 | BJ11: 58967 | BK11: 58147 | BL11: 57326 | BM11: 56505 | BN11: 55685 | BO11: 54864 | BP11: 54043 | BQ11: 53222 | BR11: 52402 | BS11: 51581 | BT11: 50760 | BU11: 49940 | BV11: 49119 | BW11: 48298 | BX11: 47478 | BY11: 46657 | BZ11: 45836 | CA11: 45015 | CB11: 44195 | CC11: 43374 | CD11: 42553 | CE11: 41733 | CF11: 40912 | CG11: 40092 | CH11: 39271 | CI11: 38450 | CJ11: 37630 | CL11: 7.6 | CM11: 1.33 | CN11: 2.676 | CO11: 3.219 | CP11: 5.429 | CQ11: 8.148 | CR11: 10.115 | CS11: 11.14 | CT11: 11.65 | CU11: 11.413 | CW11: 7.6 | CX11: 1.34 | CY11: 2.697 | CZ11: 3.244 | DA11: 5.47 | DB11: 8.195 | DC11: 10.157 | DD11: 11.162 | DE11: 11.667 | DF11: 11.429
B12: B4 | C12: 13346.9 | D12: 13080 | E12: 72.42 | F12: 0 | G12: 10.21 | H12: 63136 | J12: D Rosca | K12: 11044.1 | M12: T | N12: 12.801 | O12: 66105 | P12: 55061 | R12: L aft | S12: 14.4 | T12: 0.2 | W12: 17.375 | X12: 0.4 | Y12: 12271.4 | Z12: 2113 | AA12: 158.6 | AB12: 9.99 | AD12: 17.575 | AE12: 0.4 | AF12: 13156.4 | AG12: 2603 | AH12: 130.02 | AI12: 10.07 | AK12: 17.575 | AL12: 0.4 | AM12: 13158.2 | AN12: 2603 | AO12: 101.22 | AP12: 10.07 | AR12: 17.575 | AS12: 0.4 | AT12: 13156.5 | AU12: 2603 | AV12: 72.42 | AW12: 10.07 | AY12: 17.575 | AZ12: 0.4 | BA12: 13072.3 | BB12: 2603 | BC12: 43.25 | BD12: 10.39 | BF12: 7.7 | BG12: 61597 | BH12: 60765 | BI12: 59932 | BJ12: 59100 | BK12: 58267 | BL12: 57435 | BM12: 56602 | BN12: 55770 | BO12: 54938 | BP12: 54105 | BQ12: 53272 | BR12: 52440 | BS12: 51607 | BT12: 50775 | BU12: 49942 | BV12: 49110 | BW12: 48277 | BX12: 47445 | BY12: 46613 | BZ12: 45780 | CA12: 44947 | CB12: 44115 | CC12: 43282 | CD12: 42450 | CE12: 41617 | CF12: 40785 | CG12: 39953 | CH12: 39120 | CI12: 38288 | CJ12: 37456 | CL12: 7.7 | CM12: 1.322 | CN12: 2.662 | CO12: 3.202 | CP12: 5.399 | CQ12: 8.121 | CR12: 10.087 | CS12: 11.115 | CT12: 11.636 | CU12: 11.406 | CW12: 7.7 | CX12: 1.332 | CY12: 2.682 | CZ12: 3.226 | DA12: 5.439 | DB12: 8.167 | DC12: 10.129 | DD12: 11.137 | DE12: 11.653 | DF12: 11.421
B13: B5 | C13: 13271.5 | D13: 13006.1 | E13: 43.26 | F13: 0 | G13: 10.52 | H13: 66827 | J13: LCG | K13: 84.08 | M13: S | N13: 12.54 | O13: 64609 | P13: 53565 | R13: L fwd | S13: 0.85 | T13: 0.85 | W13: 17.175 | X13: 0.6 | Y13: 12190.4 | Z13: 2770 | AA13: 158.61 | AB13: 9.93 | AD13: 17.375 | AE13: 0.6 | AF13: 13059.9 | AG13: 3384 | AH13: 130.02 | AI13: 10 | AK13: 17.375 | AL13: 0.6 | AM13: 13061.7 | AN13: 3384 | AO13: 101.22 | AP13: 10 | AR13: 17.375 | AS13: 0.6 | AT13: 13059.9 | AU13: 3384 | AV13: 72.42 | AW13: 10 | AY13: 17.375 | AZ13: 0.6 | BA13: 12975.8 | BB13: 3384 | BC13: 43.25 | BD13: 10.32 | BF13: 7.8 | BG13: 61776 | BH13: 60932 | BI13: 60087 | BJ13: 59243 | BK13: 58399 | BL13: 57554 | BM13: 56710 | BN13: 55866 | BO13: 55022 | BP13: 54177 | BQ13: 53332 | BR13: 52488 | BS13: 51644 | BT13: 50799 | BU13: 49955 | BV13: 49111 | BW13: 48267 | BX13: 47422 | BY13: 46578 | BZ13: 45734 | CA13: 44889 | CB13: 44045 | CC13: 43201 | CD13: 42356 | CE13: 41512 | CF13: 40668 | CG13: 39824 | CH13: 38980 | CI13: 38135 | CJ13: 37291 | CL13: 7.8 | CM13: 1.315 | CN13: 2.647 | CO13: 3.184 | CP13: 5.37 | CQ13: 8.094 | CR13: 10.059 | CS13: 11.091 | CT13: 11.623 | CU13: 11.399 | CW13: 7.8 | CX13: 1.325 | CY13: 2.667 | CZ13: 3.208 | DA13: 5.409 | DB13: 8.14 | DC13: 10.1 | DD13: 11.113 | DE13: 11.639 | DF13: 11.414
J14: VCG | K14: 11.85 | M14: W | N14: 12.279 | O14: 63116 | P14: 52072 | R14: Epp | S14: 183.25 | T14: 183.25 | W14: 16.975 | X14: 0.8 | Y14: 12108.6 | Z14: 3390 | AA14: 158.62 | AB14: 9.87 | AD14: 17.175 | AE14: 0.8 | AF14: 12963.3 | AG14: 4122 | AH14: 130.02 | AI14: 9.94 | AK14: 17.175 | AL14: 0.8 | AM14: 12965.1 | AN14: 4122 | AO14: 101.22 | AP14: 9.94 | AR14: 17.175 | AS14: 0.8 | AT14: 12963.4 | AU14: 4122 | AV14: 72.42 | AW14: 9.94 | AY14: 17.175 | AZ14: 0.8 | BA14: 12879.2 | BB14: 4120 | BC14: 43.25 | BD14: 10.26 | BF14: 7.9 | BG14: 61966 | BH14: 61110 | BI14: 60254 | BJ14: 59397 | BK14: 58541 | BL14: 57685 | BM14: 56829 | BN14: 55973 | BO14: 55117 | BP14: 54260 | BQ14: 53404 | BR14: 52547 | BS14: 51691 | BT14: 50835 | BU14: 49979 | BV14: 49123 | BW14: 48267 | BX14: 47411 | BY14: 46555 | BZ14: 45698 | CA14: 44842 | CB14: 43986 | CC14: 43130 | CD14: 42274 | CE14: 41418 | CF14: 40562 | CG14: 39705 | CH14: 38849 | CI14: 37993 | CJ14: 37137 | CL14: 7.9 | CM14: 1.308 | CN14: 2.634 | CO14: 3.168 | CP14: 5.342 | CQ14: 8.067 | CR14: 10.029 | CS14: 11.068 | CT14: 11.608 | CU14: 11.391 | CW14: 7.9 | CX14: 1.318 | CY14: 2.653 | CZ14: 3.191 | DA14: 5.381 | DB14: 8.113 | DC14: 10.071 | DD14: 11.089 | DE14: 11.624 | DF14: 11.405
B15: Total Bodegas | C15: 65752 | D15: 64437 | E15: 100.38 | F15: 0 | G15: 10.26 | W15: 16.775 | X15: 1 | Y15: 12026.1 | Z15: 4032 | AA15: 158.62 | AB15: 9.81 | AD15: 16.975 | AE15: 1 | AF15: 12867 | AG15: 4943 | AH15: 130.02 | AI15: 9.87 | AK15: 16.975 | AL15: 1 | AM15: 12868.6 | AN15: 4943 | AO15: 101.22 | AP15: 9.87 | AR15: 16.975 | AS15: 1 | AT15: 12866.8 | AU15: 4943 | AV15: 72.42 | AW15: 9.87 | AY15: 16.975 | AZ15: 1 | BA15: 12782.7 | BB15: 4934 | BC15: 43.24 | BD15: 10.19 | BF15: 8 | BG15: 62180 | BH15: 61312 | BI15: 60444 | BJ15: 59576 | BK15: 58708 | BL15: 57840 | BM15: 56972 | BN15: 56104 | BO15: 55236 | BP15: 54368 | BQ15: 53500 | BR15: 52632 | BS15: 51764 | BT15: 50896 | BU15: 50028 | BV15: 49159 | BW15: 48292 | BX15: 47423 | BY15: 46556 | BZ15: 45687 | CA15: 44819 | CB15: 43951 | CC15: 43083 | CD15: 42215 | CE15: 41347 | CF15: 40479 | CG15: 39611 | CH15: 38743 | CI15: 37875 | CJ15: 37007 | CL15: 8 | CM15: 1.302 | CN15: 2.62 | CO15: 3.152 | CP15: 5.315 | CQ15: 8.041 | CR15: 10 | CS15: 11.045 | CT15: 11.593 | CU15: 11.383 | CW15: 8 | CX15: 1.312 | CY15: 2.64 | CZ15: 3.175 | DA15: 5.353 | DB15: 8.086 | DC15: 10.041 | DD15: 11.066 | DE15: 11.609 | DF15: 11.397
J16: Calado Aereo | K16: 45.6 | W16: 16.575 | X16: 1.2 | Y16: 11942.9 | Z16: 4685 | AA16: 158.63 | AB16: 9.75 | AD16: 16.775 | AE16: 1.2 | AF16: 12770.2 | AG16: 5781 | AH16: 130.02 | AI16: 9.8 | AK16: 16.775 | AL16: 1.2 | AM16: 12772 | AN16: 5781 | AO16: 101.22 | AP16: 9.8 | AR16: 16.775 | AS16: 1.2 | AT16: 12770.3 | AU16: 5781 | AV16: 72.42 | AW16: 9.8 | AY16: 16.775 | AZ16: 1.2 | BA16: 12686.1 | BB16: 5767 | BC16: 43.24 | BD16: 10.13 | BF16: 8.1 | BG16: 62394 | BH16: 61514 | BI16: 60635 | BJ16: 59755 | BK16: 58875 | BL16: 57995 | BM16: 57115 | BN16: 56235 | BO16: 55355 | BP16: 54475 | BQ16: 53594 | BR16: 52715 | BS16: 51835 | BT16: 50955 | BU16: 50075 | BV16: 49195 | BW16: 48315 | BX16: 47435 | BY16: 46555 | BZ16: 45675 | CA16: 44795 | CB16: 43915 | CC16: 43035 | CD16: 42155 | CE16: 41275 | CF16: 40395 | CG16: 39516 | CH16: 38636 | CI16: 37756 | CJ16: 36876 | CL16: 8.1 | CM16: 1.296 | CN16: 2.608 | CO16: 3.137 | CP16: 5.289 | CQ16: 8.015 | CR16: 9.97 | CS16: 11.023 | CT16: 11.578 | CU16: 11.375 | CW16: 8.1 | CX16: 1.305 | CY16: 2.627 | CZ16: 3.159 | DA16: 5.326 | DB16: 8.06 | DC16: 10.01 | DD16: 11.043 | DE16: 11.593 | DF16: 11.388
W17: 16.375 | X17: 1.4 | Y17: 11859 | Z17: 5328 | AA17: 158.64 | AB17: 9.69 | AD17: 16.575 | AE17: 1.4 | AF17: 12673.7 | AG17: 6581 | AH17: 130.02 | AI17: 9.74 | AK17: 16.575 | AL17: 1.4 | AM17: 12675.5 | AN17: 6581 | AO17: 101.22 | AP17: 9.74 | AR17: 16.575 | AS17: 1.4 | AT17: 12673.7 | AU17: 6581 | AV17: 72.42 | AW17: 9.74 | AY17: 16.575 | AZ17: 1.4 | BA17: 12589.6 | BB17: 6565 | BC17: 43.24 | BD17: 10.06 | BF17: 8.2 | BG17: 62618 | BH17: 61726 | BI17: 60834 | BJ17: 59942 | BK17: 59051 | BL17: 58159 | BM17: 57267 | BN17: 56375 | BO17: 55483 | BP17: 54591 | BQ17: 53699 | BR17: 52807 | BS17: 51915 | BT17: 51023 | BU17: 50131 | BV17: 49239 | BW17: 48348 | BX17: 47456 | BY17: 46564 | BZ17: 45672 | CA17: 44780 | CB17: 43888 | CC17: 42996 | CD17: 42104 | CE17: 41213 | CF17: 40321 | CG17: 39429 | CH17: 38537 | CI17: 37645 | CJ17: 36754 | CL17: 8.2 | CM17: 1.29 | CN17: 2.596 | CO17: 3.122 | CP17: 5.264 | CQ17: 7.989 | CR17: 9.939 | CS17: 11.001 | CT17: 11.562 | CU17: 11.366 | CW17: 8.2 | CX17: 1.299 | CY17: 2.614 | CZ17: 3.144 | DA17: 5.301 | DB17: 8.034 | DC17: 9.979 | DD17: 11.021 | DE17: 11.577 | DF17: 11.379
W18: 16.175 | X18: 1.6 | Y18: 11774.3 | Z18: 5952 | AA18: 158.65 | AB18: 9.63 | AD18: 16.375 | AE18: 1.6 | AF18: 12577.1 | AG18: 7347 | AH18: 130.02 | AI18: 9.67 | AK18: 16.375 | AL18: 1.6 | AM18: 12578.9 | AN18: 7347 | AO18: 101.22 | AP18: 9.67 | AR18: 16.375 | AS18: 1.6 | AT18: 12577.1 | AU18: 7347 | AV18: 72.42 | AW18: 9.67 | AY18: 16.375 | AZ18: 1.6 | BA18: 12493 | BB18: 7330 | BC18: 43.24 | BD18: 10 | BF18: 8.3 | BG18: 62852 | BH18: 61949 | BI18: 61045 | BJ18: 60141 | BK18: 59237 | BL18: 58333 | BM18: 57429 | BN18: 56525 | BO18: 55622 | BP18: 54718 | BQ18: 53813 | BR18: 52910 | BS18: 52006 | BT18: 51102 | BU18: 50198 | BV18: 49294 | BW18: 48391 | BX18: 47487 | BY18: 46583 | BZ18: 45679 | CA18: 44775 | CB18: 43871 | CC18: 42967 | CD18: 42064 | CE18: 41160 | CF18: 40256 | CG18: 39352 | CH18: 38449 | CI18: 37545 | CJ18: 36641 | CL18: 8.3 | CM18: 1.284 | CN18: 2.584 | CO18: 3.108 | CP18: 5.24 | CQ18: 7.963 | CR18: 9.908 | CS18: 10.98 | CT18: 11.546 | CU18: 11.357 | CW18: 8.3 | CX18: 1.293 | CY18: 2.603 | CZ18: 3.13 | DA18: 5.276 | DB18: 8.008 | DC18: 9.948 | DD18: 10.999 | DE18: 11.56 | DF18: 11.369
W19: 15.975 | X19: 1.8 | Y19: 11688.9 | Z19: 6552 | AA19: 158.65 | AB19: 9.57 | AD19: 16.175 | AE19: 1.8 | AF19: 12480.5 | AG19: 8081 | AH19: 130.02 | AI19: 9.61 | AK19: 16.175 | AL19: 1.8 | AM19: 12482.4 | AN19: 8081 | AO19: 101.22 | AP19: 9.61 | AR19: 16.175 | AS19: 1.8 | AT19: 12480.6 | AU19: 8081 | AV19: 72.42 | AW19: 9.61 | AY19: 16.175 | AZ19: 1.8 | BA19: 12396.5 | BB19: 8061 | BC19: 43.23 | BD19: 9.94 | BF19: 8.4 | BG19: 63097 | BH19: 62181 | BI19: 61265 | BJ19: 60349 | BK19: 59433 | BL19: 58518 | BM19: 57602 | BN19: 56686 | BO19: 55770 | BP19: 54854 | BQ19: 53938 | BR19: 53022 | BS19: 52107 | BT19: 51191 | BU19: 50275 | BV19: 49359 | BW19: 48443 | BX19: 47528 | BY19: 46612 | BZ19: 45696 | CA19: 44780 | CB19: 43864 | CC19: 42948 | CD19: 42032 | CE19: 41117 | CF19: 40201 | CG19: 39285 | CH19: 38369 | CI19: 37454 | CJ19: 36538 | CL19: 8.4 | CM19: 1.279 | CN19: 2.573 | CO19: 3.095 | CP19: 5.217 | CQ19: 7.938 | CR19: 9.877 | CS19: 10.959 | CT19: 11.529 | CU19: 11.348 | CW19: 8.4 | CX19: 1.288 | CY19: 2.591 | CZ19: 3.116 | DA19: 5.253 | DB19: 7.982 | DC19: 9.916 | DD19: 10.978 | DE19: 11.543 | DF19: 11.359
B20: Water Ballast | C20: Vol 100% | D20: Vol 98% | E20: LCG | F20: TCG | G20: VCG | H20: FSM (m4) | W20: 15.775 | X20: 2 | Y20: 11603.1 | Z20: 7126 | AA20: 158.66 | AB20: 9.51 | AD20: 15.975 | AE20: 2 | AF20: 12384 | AG20: 8784 | AH20: 130.02 | AI20: 9.54 | AK20: 15.975 | AL20: 2 | AM20: 12385.8 | AN20: 8784 | AO20: 101.22 | AP20: 9.54 | AR20: 15.975 | AS20: 2 | AT20: 12384 | AU20: 8784 | AV20: 72.42 | AW20: 9.54 | AY20: 15.975 | AZ20: 2 | BA20: 12299.9 | BB20: 8761 | BC20: 43.23 | BD20: 9.87 | BF20: 8.5 | BG20: 63352 | BH20: 62424 | BI20: 61496 | BJ20: 60568 | BK20: 59640 | BL20: 58713 | BM20: 57785 | BN20: 56857 | BO20: 55929 | BP20: 55001 | BQ20: 54073 | BR20: 53145 | BS20: 52217 | BT20: 51290 | BU20: 50362 | BV20: 49434 | BW20: 48506 | BX20: 47578 | BY20: 46651 | BZ20: 45723 | CA20: 44794 | CB20: 43867 | CC20: 42939 | CD20: 42011 | CE20: 41083 | CF20: 40156 | CG20: 39228 | CH20: 38300 | CI20: 37372 | CJ20: 36445 | CL20: 8.5 | CM20: 1.274 | CN20: 2.562 | CO20: 3.082 | CP20: 5.195 | CQ20: 7.912 | CR20: 9.845 | CS20: 10.938 | CT20: 11.511 | CU20: 11.339 | CW20: 8.5 | CX20: 1.282 | CY20: 2.58 | CZ20: 3.103 | DA20: 5.23 | DB20: 7.957 | DC20: 9.883 | DD20: 10.957 | DE20: 11.526 | DF20: 11.349
B21: Fore Peak tank | C21: 1874.3 | D21: 1836.8 | E21: 179.02 | F21: 0 | G21: 9.3 | H21: 4265 | J21: Draft (m) | K21: D tm | L21: DW tm | M21: LCB (m) | N21: VCB (m) | O21: LCF (m) | P21: KMT (m) | Q21: MCT (Tm*m) | R21: TCP (Tm/cm) | S21: CB | T21: WLA (m2) | U21: WSA (m2) | W21: 15.575 | X21: 2.2 | Y21: 11516.7 | Z21: 7678 | AA21: 158.67 | AB21: 9.45 | AD21: 15.775 | AE21: 2.2 | AF21: 12287.4 | AG21: 9458 | AH21: 130.02 | AI21: 9.48 | AK21: 15.775 | AL21: 2.2 | AM21: 12289.2 | AN21: 9458 | AO21: 101.22 | AP21: 9.48 | AR21: 15.775 | AS21: 2.2 | AT21: 12287.5 | AU21: 9458 | AV21: 72.42 | AW21: 9.48 | AY21: 15.775 | AZ21: 2.2 | BA21: 12203.4 | BB21: 9430 | BC21: 43.23 | BD21: 9.81 | BF21: 8.6 | BG21: 63618 | BH21: 62678 | BI21: 61738 | BJ21: 60799 | BK21: 59859 | BL21: 58919 | BM21: 57979 | BN21: 57039 | BO21: 56099 | BP21: 55160 | BQ21: 54219 | BR21: 53279 | BS21: 52339 | BT21: 51400 | BU21: 50460 | BV21: 49520 | BW21: 48580 | BX21: 47640 | BY21: 46700 | BZ21: 45761 | CA21: 44820 | CB21: 43880 | CC21: 42941 | CD21: 42001 | CE21: 41061 | CF21: 40121 | CG21: 39181 | CH21: 38242 | CI21: 37302 | CJ21: 36362 | CL21: 8.6 | CM21: 1.269 | CN21: 2.552 | CO21: 3.069 | CP21: 5.174 | CQ21: 7.887 | CR21: 9.814 | CS21: 10.918 | CT21: 11.494 | CU21: 11.329 | CW21: 8.6 | CX21: 1.277 | CY21: 2.57 | CZ21: 3.09 | DA21: 5.208 | DB21: 7.932 | DC21: 9.851 | DD21: 10.936 | DE21: 11.508 | DF21: 11.339
B22: DB Ballast P 1 | C22: 245.5 | D22: 240.6 | E22: 157.12 | F22: -5.15 | G22: 0.91 | H22: 448 | J22: 2.5 | K22: 11203 | L22: 159 | M22: 101.38 | N22: 1.29 | O22: 100.7 | P22: 33.47 | Q22: 493.3 | R22: 48 | S22: 0.734 | T22: 4681 | U22: 5164 | W22: 15.375 | X22: 2.4 | Y22: 11426.9 | Z22: 8240 | AA22: 158.68 | AB22: 9.38 | AD22: 15.575 | AE22: 2.4 | AF22: 12185.6 | AG22: 10163 | AH22: 130.02 | AI22: 9.41 | AK22: 15.575 | AL22: 2.4 | AM22: 12187.4 | AN22: 10163 | AO22: 101.22 | AP22: 9.41 | AR22: 15.575 | AS22: 2.4 | AT22: 12185.6 | AU22: 10163 | AV22: 72.42 | AW22: 9.41 | AY22: 15.575 | AZ22: 2.4 | BA22: 12102.1 | BB22: 10125 | BC22: 43.22 | BD22: 9.75 | BF22: 8.7 | BG22: 63894 | BH22: 62942 | BI22: 61991 | BJ22: 61039 | BK22: 60087 | BL22: 59135 | BM22: 58183 | BN22: 57231 | BO22: 56279 | BP22: 55327 | BQ22: 54375 | BR22: 53423 | BS22: 52471 | BT22: 51519 | BU22: 50567 | BV22: 49615 | BW22: 48663 | BX22: 47712 | BY22: 46760 | BZ22: 45808 | CA22: 44855 | CB22: 43904 | CC22: 42952 | CD22: 42000 | CE22: 41048 | CF22: 40096 | CG22: 39144 | CH22: 38193 | CI22: 37241 | CJ22: 36289 | CL22: 8.7 | CM22: 1.264 | CN22: 2.542 | CO22: 3.057 | CP22: 5.154 | CQ22: 7.861 | CR22: 9.782 | CS22: 10.897 | CT22: 11.476 | CU22: 11.319 | CW22: 8.7 | CX22: 1.272 | CY22: 2.559 | CZ22: 3.078 | DA22: 5.187 | DB22: 7.906 | DC22: 9.818 | DD22: 10.916 | DE22: 11.489 | DF22: 11.328
B23: DB Ballast S 1 | C23: 245.5 | D23: 240.6 | E23: 157.12 | F23: 5.15 | G23: 0.91 | H23: 448 | J23: 2.6 | K23: 11683 | L23: 639 | M23: 101.38 | N23: 1.29 | O23: 100.7 | P23: 33.47 | Q23: 493.3 | R23: 48 | S23: 0.734 | T23: 4681 | U23: 5164 | W23: 15.175 | X23: 2.6 | Y23: 11333 | Z23: 8819 | AA23: 158.69 | AB23: 9.31 | AD23: 15.375 | AE23: 2.6 | AF23: 12078.3 | AG23: 10895 | AH23: 130.02 | AI23: 9.34 | AK23: 15.375 | AL23: 2.6 | AM23: 12080.1 | AN23: 10895 | AO23: 101.22 | AP23: 9.34 | AR23: 15.375 | AS23: 2.6 | AT23: 12078.4 | AU23: 10895 | AV23: 72.42 | AW23: 9.34 | AY23: 15.375 | AZ23: 2.6 | BA23: 11996 | BB23: 10841 | BC23: 43.22 | BD23: 9.68 | BF23: 8.8 | BG23: 64180 | BH23: 63216 | BI23: 62252 | BJ23: 61288 | BK23: 60324 | BL23: 59360 | BM23: 58396 | BN23: 57432 | BO23: 56468 | BP23: 55504 | BQ23: 54539 | BR23: 53575 | BS23: 52611 | BT23: 51647 | BU23: 50683 | BV23: 49719 | BW23: 48755 | BX23: 47791 | BY23: 46827 | BZ23: 45863 | CA23: 44899 | CB23: 43935 | CC23: 42971 | CD23: 42007 | CE23: 41043 | CF23: 40079 | CG23: 39115 | CH23: 38151 | CI23: 37188 | CJ23: 36224 | CL23: 8.8 | CM23: 1.259 | CN23: 2.533 | CO23: 3.046 | CP23: 5.135 | CQ23: 7.835 | CR23: 9.749 | CS23: 10.876 | CT23: 11.457 | CU23: 11.308 | CW23: 8.8 | CX23: 1.268 | CY23: 2.55 | CZ23: 3.066 | DA23: 5.167 | DB23: 7.88 | DC23: 9.784 | DD23: 10.895 | DE23: 11.47 | DF23: 11.317
B24: WT Ballast P 1 | C24: 1066.9 | D24: 1045.5 | E24: 158.83 | F24: -12.75 | G24: 7.19 | H24: 1407 | J24: 2.7 | K24: 12165 | L24: 1121 | M24: 101.32 | N24: 1.34 | O24: 100.66 | P24: 32.35 | Q24: 497.1 | R24: 48.1 | S24: 0.736 | T24: 4696 | U24: 5207 | W24: 14.975 | X24: 2.8 | Y24: 11235.7 | Z24: 9404 | AA24: 158.69 | AB24: 9.25 | AD24: 15.175 | AE24: 2.8 | AF24: 11971 | AG24: 11605 | AH24: 130.02 | AI24: 9.27 | AK24: 15.175 | AL24: 2.8 | AM24: 11972.8 | AN24: 11605 | AO24: 101.22 | AP24: 9.27 | AR24: 15.175 | AS24: 2.8 | AT24: 11971.1 | AU24: 11605 | AV24: 72.42 | AW24: 9.27 | AY24: 15.175 | AZ24: 2.8 | BA24: 11889.9 | BB24: 11535 | BC24: 43.21 | BD24: 9.62 | BF24: 8.9 | BG24: 64475 | BH24: 63499 | BI24: 62523 | BJ24: 61547 | BK24: 60571 | BL24: 59595 | BM24: 58619 | BN24: 57643 | BO24: 56666 | BP24: 55690 | BQ24: 54714 | BR24: 53738 | BS24: 52762 | BT24: 51785 | BU24: 50809 | BV24: 49833 | BW24: 48857 | BX24: 47881 | BY24: 46905 | BZ24: 45929 | CA24: 44952 | CB24: 43976 | CC24: 43000 | CD24: 42024 | CE24: 41048 | CF24: 40072 | CG24: 39096 | CH24: 38120 | CI24: 37144 | CJ24: 36168 | CL24: 8.9 | CM24: 1.255 | CN24: 2.524 | CO24: 3.035 | CP24: 5.116 | CQ24: 7.809 | CR24: 9.717 | CS24: 10.856 | CT24: 11.438 | CU24: 11.298 | CW24: 8.9 | CX24: 1.263 | CY24: 2.54 | CZ24: 3.055 | DA24: 5.148 | DB24: 7.854 | DC24: 9.751 | DD24: 10.875 | DE24: 11.451 | DF24: 11.306
B25: WT Ballast S 1 | C25: 1066.9 | D25: 1045.5 | E25: 158.83 | F25: 12.75 | G25: 7.19 | H25: 1407 | J25: 2.8 | K25: 12649 | L25: 1605 | M25: 101.29 | N25: 1.44 | O25: 100.57 | P25: 30.36 | Q25: 504.4 | R25: 48.4 | S25: 0.74 | T25: 4724 | U25: 5250 | W25: 14.775 | X25: 3 | Y25: 11133.3 | Z25: 10017 | AA25: 158.7 | AB25: 9.18 | AD25: 14.975 | AE25: 3 | AF25: 11863.7 | AG25: 12283 | AH25: 130.02 | AI25: 9.2 | AK25: 14.975 | AL25: 3 | AM25: 11865.6 | AN25: 12283 | AO25: 101.22 | AP25: 9.2 | AR25: 14.975 | AS25: 3 | AT25: 11863.8 | AU25: 12283 | AV25: 72.42 | AW25: 9.2 | AY25: 14.975 | AZ25: 3 | BA25: 11783.8 | BB25: 12196 | BC25: 43.21 | BD25: 9.55 | BF25: 9 | BG25: 64781 | BH25: 63792 | BI25: 62804 | BJ25: 61816 | BK25: 60827 | BL25: 59839 | BM25: 58851 | BN25: 57863 | BO25: 56874 | BP25: 55886 | BQ25: 54897 | BR25: 53909 | BS25: 52921 | BT25: 51933 | BU25: 50944 | BV25: 49956 | BW25: 48968 | BX25: 47980 | BY25: 46991 | BZ25: 46003 | CA25: 45014 | CB25: 44026 | CC25: 43038 | CD25: 42050 | CE25: 41062 | CF25: 40073 | CG25: 39085 | CH25: 38097 | CI25: 37109 | CJ25: 36121 | CL25: 9 | CM25: 1.251 | CN25: 2.515 | CO25: 3.025 | CP25: 5.098 | CQ25: 7.782 | CR25: 9.685 | CS25: 10.835 | CT25: 11.419 | CU25: 11.287 | CW25: 9 | CX25: 1.259 | CY25: 2.532 | CZ25: 3.044 | DA25: 5.13 | DB25: 7.827 | DC25: 9.717 | DD25: 10.855 | DE25: 11.432 | DF25: 11.295
B26: DB Ballast P 2 | C26: 607.7 | D26: 595.6 | E26: 132.91 | F26: -7.49 | G26: 1.24 | H26: 2680 | J26: 2.9 | K26: 13134 | L26: 2090 | M26: 101.26 | N26: 1.49 | O26: 100.53 | P26: 29.48 | Q26: 508 | R26: 48.6 | S26: 0.742 | T26: 4738 | U26: 5293 | W26: 14.575 | X26: 3.2 | Y26: 11027.5 | Z26: 10634 | AA26: 158.71 | AB26: 9.12 | AD26: 14.775 | AE26: 3.2 | AF26: 11756.5 | AG26: 12929 | AH26: 130.02 | AI26: 9.13 | AK26: 14.775 | AL26: 3.2 | AM26: 11758.3 | AN26: 12929 | AO26: 101.22 | AP26: 9.13 | AR26: 14.775 | AS26: 3.2 | AT26: 11756.5 | AU26: 12929 | AV26: 72.42 | AW26: 9.13 | AY26: 14.775 | AZ26: 3.2 | BA26: 11677.7 | BB26: 12825 | BC26: 43.21 | BD26: 9.48 | BF26: 9.1 | BG26: 65068 | BH26: 64067 | BI26: 63067 | BJ26: 62066 | BK26: 61066 | BL26: 60065 | BM26: 59065 | BN26: 58065 | BO26: 57064 | BP26: 56064 | BQ26: 55063 | BR26: 54062 | BS26: 53062 | BT26: 52062 | BU26: 51061 | BV26: 50061 | BW26: 49061 | BX26: 48060 | BY26: 47060 | BZ26: 46059 | CA26: 45059 | CB26: 44058 | CC26: 43058 | CD26: 42057 | CE26: 41057 | CF26: 40057 | CG26: 39056 | CH26: 38056 | CI26: 37056 | CJ26: 36056 | CL26: 9.1 | CM26: 1.247 | CN26: 2.507 | CO26: 3.015 | CP26: 5.081 | CQ26: 7.755 | CR26: 9.652 | CS26: 10.814 | CT26: 11.399 | CU26: 11.276 | CW26: 9.1 | CX26: 1.255 | CY26: 2.523 | CZ26: 3.034 | DA26: 5.112 | DB26: 7.799 | DC26: 9.684 | DD26: 10.834 | DE26: 11.412 | DF26: 11.283
B27: DB Ballast S 2 | C27: 607.7 | D27: 595.6 | E27: 132.91 | F27: 7.49 | G27: 1.24 | H27: 2680 | J27: 3 | K27: 13620 | L27: 2576 | M27: 101.24 | N27: 1.55 | O27: 100.49 | P27: 28.65 | Q27: 511.6 | R27: 48.7 | S27: 0.744 | T27: 4751 | U27: 5336 | W27: 14.375 | X27: 3.4 | Y27: 10917.6 | Z27: 11262 | AA27: 158.71 | AB27: 9.05 | AD27: 14.575 | AE27: 3.4 | AF27: 11649.2 | AG27: 13544 | AH27: 130.02 | AI27: 9.06 | AK27: 14.575 | AL27: 3.4 | AM27: 11651 | AN27: 13544 | AO27: 101.22 | AP27: 9.07 | AR27: 14.575 | AS27: 3.4 | AT27: 11649.2 | AU27: 13544 | AV27: 72.42 | AW27: 9.06 | AY27: 14.575 | AZ27: 3.4 | BA27: 11564.8 | BB27: 13504 | BC27: 43.22 | BD27: 9.41 | BF27: 9.2 | BG27: 65392 | BH27: 64379 | BI27: 63367 | BJ27: 62354 | BK27: 61342 | BL27: 60329 | BM27: 59316 | BN27: 58304 | BO27: 57291 | BP27: 56279 | BQ27: 55266 | BR27: 54253 | BS27: 53240 | BT27: 52228 | BU27: 51215 | BV27: 50203 | BW27: 49190 | BX27: 48178 | BY27: 47165 | BZ27: 46153 | CA27: 45139 | CB27: 44127 | CC27: 43114 | CD27: 42102 | CE27: 41089 | CF27: 40077 | CG27: 39064 | CH27: 38052 | CI27: 37039 | CJ27: 36027 | CL27: 9.2 | CM27: 1.243 | CN27: 2.499 | CO27: 3.005 | CP27: 5.065 | CQ27: 7.728 | CR27: 9.62 | CS27: 10.793 | CT27: 11.379 | CU27: 11.264 | CW27: 9.2 | CX27: 1.251 | CY27: 2.515 | CZ27: 3.024 | DA27: 5.095 | DB27: 7.771 | DC27: 9.65 | DD27: 10.813 | DE27: 11.392 | DF27: 11.272
B28: WT Ballast P 2 | C28: 1008.5 | D28: 988.3 | E28: 130.6 | F28: -14.86 | G28: 8.9 | H28: 90 | J28: 3.1 | K28: 14108 | L28: 3064 | M28: 101.21 | N28: 1.6 | O28: 100.45 | P28: 27.88 | Q28: 514.9 | R28: 48.8 | S28: 0.746 | T28: 4764 | U28: 5422 | W28: 14.175 | X28: 3.6 | Y28: 10802.9 | Z28: 11908 | AA28: 158.71 | AB28: 8.97 | AD28: 14.375 | AE28: 3.6 | AF28: 11541.9 | AG28: 14130 | AH28: 130.02 | AI28: 9 | AK28: 14.375 | AL28: 3.6 | AM28: 11543.7 | AN28: 14130 | AO28: 101.22 | AP28: 9 | AR28: 14.375 | AS28: 3.6 | AT28: 11542 | AU28: 14130 | AV28: 72.42 | AW28: 9 | AY28: 14.375 | AZ28: 3.6 | BA28: 11442.1 | BB28: 14281 | BC28: 43.22 | BD28: 9.34 | BF28: 9.3 | BG28: 65726 | BH28: 64701 | BI28: 63676 | BJ28: 62651 | BK28: 61627 | BL28: 60602 | BM28: 59577 | BN28: 58552 | BO28: 57528 | BP28: 56503 | BQ28: 55477 | BR28: 54452 | BS28: 53428 | BT28: 52403 | BU28: 51378 | BV28: 50353 | BW28: 49329 | BX28: 48304 | BY28: 47279 | BZ28: 46254 | CA28: 45229 | CB28: 44204 | CC28: 43179 | CD28: 42155 | CE28: 41130 | CF28: 40105 | CG28: 39081 | CH28: 38056 | CI28: 37031 | CJ28: 36007 | CL28: 9.3 | CM28: 1.239 | CN28: 2.492 | CO28: 2.996 | CP28: 5.049 | CQ28: 7.7 | CR28: 9.588 | CS28: 10.771 | CT28: 11.359 | CU28: 11.253 | CW28: 9.3 | CX28: 1.247 | CY28: 2.507 | CZ28: 3.014 | DA28: 5.079 | DB28: 7.743 | DC28: 9.617 | DD28: 10.791 | DE28: 11.372 | DF28: 11.26
B29: WT Ballast S 2 | C29: 1008.5 | D29: 988.3 | E29: 130.6 | F29: 14.86 | G29: 8.9 | H29: 90 | J29: 3.2 | K29: 14597 | L29: 3553 | M29: 101.18 | N29: 1.65 | O29: 100.41 | P29: 27.16 | Q29: 518.2 | R29: 49 | S29: 0.748 | T29: 4776 | U29: 5464 | W29: 13.975 | X29: 3.8 | Y29: 10685.1 | Z29: 12548 | AA29: 158.72 | AB29: 8.9 | AD29: 14.175 | AE29: 3.8 | AF29: 11427.6 | AG29: 14778 | AH29: 130.02 | AI29: 8.93 | AK29: 14.175 | AL29: 3.8 | AM29: 11429.4 | AN29: 14778 | AO29: 101.22 | AP29: 8.93 | AR29: 14.175 | AS29: 3.8 | AT29: 11427.7 | AU29: 14778 | AV29: 72.42 | AW29: 8.93 | AY29: 14.175 | AZ29: 3.8 | BA29: 11315.8 | BB29: 15064 | BC29: 43.23 | BD29: 9.27 | BF29: 9.4 | BG29: 66069 | BH29: 65032 | BI29: 63995 | BJ29: 62958 | BK29: 61921 | BL29: 60884 | BM29: 59847 | BN29: 58810 | BO29: 57773 | BP29: 56736 | BQ29: 55698 | BR29: 54661 | BS29: 53624 | BT29: 52587 | BU29: 51550 | BV29: 50513 | BW29: 49476 | BX29: 48439 | BY29: 47402 | BZ29: 46365 | CA29: 45327 | CB29: 44290 | CC29: 43254 | CD29: 42217 | CE29: 41180 | CF29: 40143 | CG29: 39106 | CH29: 38069 | CI29: 37032 | CJ29: 35995 | CL29: 9.4 | CM29: 1.236 | CN29: 2.484 | CO29: 2.987 | CP29: 5.034 | CQ29: 7.673 | CR29: 9.556 | CS29: 10.749 | CT29: 11.339 | CU29: 11.241 | CW29: 9.4 | CX29: 1.243 | CY29: 2.5 | CZ29: 3.005 | DA29: 5.063 | DB29: 7.714 | DC29: 9.585 | DD29: 10.769 | DE29: 11.351 | DF29: 11.248
B30: DB Ballast P 3 | C30: 607.7 | D30: 595.6 | E30: 104.11 | F30: -7.49 | G30: 1.24 | H30: 2680 | J30: 3.3 | K30: 15087 | L30: 4043 | M30: 101.16 | N30: 1.7 | O30: 100.37 | P30: 26.49 | Q30: 521.4 | R30: 49.1 | S30: 0.75 | T30: 4788 | U30: 5507 | W30: 13.775 | X30: 4 | Y30: 10564.3 | Z30: 13180 | AA30: 158.72 | AB30: 8.82 | AD30: 13.975 | AE30: 4 | AF30: 11306.4 | AG30: 15488 | AH30: 130.02 | AI30: 8.85 | AK30: 13.975 | AL30: 4 | AM30: 11308.2 | AN30: 15488 | AO30: 101.22 | AP30: 8.85 | AR30: 13.975 | AS30: 4 | AT30: 11306.4 | AU30: 15488 | AV30: 72.42 | AW30: 8.85 | AY30: 13.975 | AZ30: 4 | BA30: 11186 | BB30: 15855 | BC30: 43.23 | BD30: 9.19 | BF30: 9.5 | BG30: 66421 | BH30: 65372 | BI30: 64323 | BJ30: 63273 | BK30: 62224 | BL30: 61175 | BM30: 60125 | BN30: 59076 | BO30: 58027 | BP30: 56978 | BQ30: 55928 | BR30: 54879 | BS30: 53829 | BT30: 52780 | BU30: 51731 | BV30: 50682 | BW30: 49633 | BX30: 48583 | BY30: 47534 | BZ30: 46485 | CA30: 45435 | CB30: 44386 | CC30: 43337 | CD30: 42288 | CE30: 41238 | CF30: 40189 | CG30: 39140 | CH30: 38091 | CI30: 37042 | CJ30: 35993 | CL30: 9.5 | CM30: 1.232 | CN30: 2.477 | CO30: 2.979 | CP30: 5.02 | CQ30: 7.644 | CR30: 9.524 | CS30: 10.727 | CT30: 11.318 | CU30: 11.23 | CW30: 9.5 | CX30: 1.24 | CY30: 2.492 | CZ30: 2.997 | DA30: 5.049 | DB30: 7.685 | DC30: 9.552 | DD30: 10.747 | DE30: 11.33 | DF30: 11.236
B31: DB Ballast S 3 | C31: 607.7 | D31: 595.6 | E31: 104.11 | F31: 7.49 | G31: 1.24 | H31: 2680 | J31: 3.4 | K31: 15578 | L31: 4534 | M31: 101.13 | N31: 1.75 | O31: 100.35 | P31: 25.86 | Q31: 524.4 | R31: 49.2 | S31: 0.752 | T31: 4800 | U31: 5549 | W31: 13.575 | X31: 4.2 | Y31: 10438.1 | Z31: 13831 | AA31: 158.72 | AB31: 8.74 | AD31: 13.775 | AE31: 4.2 | AF31: 11181.1 | AG31: 16215 | AH31: 130.02 | AI31: 8.78 | AK31: 13.775 | AL31: 4.2 | AM31: 11182.9 | AN31: 16215 | AO31: 101.22 | AP31: 8.78 | AR31: 13.775 | AS31: 4.2 | AT31: 11181.2 | AU31: 16215 | AV31: 72.42 | AW31: 8.78 | AY31: 13.775 | AZ31: 4.2 | BA31: 11054.2 | BB31: 16632 | BC31: 43.24 | BD31: 9.11 | BF31: 9.6 | BG31: 66783 | BH31: 65722 | BI31: 64660 | BJ31: 63599 | BK31: 62537 | BL31: 61476 | BM31: 60414 | BN31: 59353 | BO31: 58291 | BP31: 57230 | BQ31: 56167 | BR31: 55106 | BS31: 54044 | BT31: 52983 | BU31: 51921 | BV31: 50860 | BW31: 49798 | BX31: 48737 | BY31: 47676 | BZ31: 46614 | CA31: 45552 | CB31: 44491 | CC31: 43429 | CD31: 42368 | CE31: 41306 | CF31: 40245 | CG31: 39184 | CH31: 38122 | CI31: 37061 | CJ31: 36000 | CL31: 9.6 | CM31: 1.229 | CN31: 2.471 | CO31: 2.971 | CP31: 5.006 | CQ31: 7.616 | CR31: 9.492 | CS31: 10.704 | CT31: 11.297 | CU31: 11.218 | CW31: 9.6 | CX31: 1.236 | CY31: 2.486 | CZ31: 2.989 | DA31: 5.034 | DB31: 7.656 | DC31: 9.52 | DD31: 10.724 | DE31: 11.309 | DF31: 11.224
B32: WT Ballast P 3 | C32: 1009.8 | D32: 989.6 | E32: 101.82 | F32: -14.86 | G32: 8.89 | H32: 91 | J32: 3.5 | K32: 16071 | L32: 5027 | M32: 101.11 | N32: 1.81 | O32: 100.32 | P32: 25.26 | Q32: 527.2 | R32: 49.3 | S32: 0.753 | T32: 4811 | U32: 5591 | W32: 13.375 | X32: 4.4 | Y32: 10308.4 | Z32: 14465 | AA32: 158.72 | AB32: 8.66 | AD32: 13.575 | AE32: 4.4 | AF32: 11049.8 | AG32: 16961 | AH32: 130.02 | AI32: 8.7 | AK32: 13.575 | AL32: 4.4 | AM32: 11051.6 | AN32: 16962 | AO32: 101.22 | AP32: 8.7 | AR32: 13.575 | AS32: 4.4 | AT32: 11049.9 | AU32: 16961 | AV32: 72.42 | AW32: 8.7 | AY32: 13.575 | AZ32: 4.4 | BA32: 10917 | BB32: 17420 | BC32: 43.25 | BD32: 9.03 | BF32: 9.7 | BG32: 67156 | BH32: 66082 | BI32: 65008 | BJ32: 63934 | BK32: 62860 | BL32: 61787 | BM32: 60713 | BN32: 59639 | BO32: 58565 | BP32: 57491 | BQ32: 56417 | BR32: 55343 | BS32: 54269 | BT32: 53196 | BU32: 52122 | BV32: 51048 | BW32: 49975 | BX32: 48901 | BY32: 47827 | BZ32: 46753 | CA32: 45679 | CB32: 44605 | CC32: 43532 | CD32: 42458 | CE32: 41384 | CF32: 40311 | CG32: 39237 | CH32: 38163 | CI32: 37090 | CJ32: 36016 | CL32: 9.7 | CM32: 1.226 | CN32: 2.465 | CO32: 2.963 | CP32: 4.993 | CQ32: 7.587 | CR32: 9.461 | CS32: 10.681 | CT32: 11.275 | CU32: 11.206 | CW32: 9.7 | CX32: 1.233 | CY32: 2.479 | CZ32: 2.981 | DA32: 5.021 | DB32: 7.626 | DC32: 9.489 | DD32: 10.701 | DE32: 11.287 | DF32: 11.212
B33: WT Ballast S 3 | C33: 1009.8 | D33: 989.6 | E33: 101.82 | F33: 14.86 | G33: 8.89 | H33: 91 | J33: 3.6 | K33: 16565 | L33: 5521 | M33: 101.08 | N33: 1.86 | O33: 100.28 | P33: 24.7 | Q33: 530 | R33: 49.4 | S33: 0.755 | T33: 4821 | U33: 5632 | W33: 13.175 | X33: 4.6 | Y33: 10174.7 | Z33: 15083 | AA33: 158.72 | AB33: 8.57 | AD33: 13.375 | AE33: 4.6 | AF33: 10914.5 | AG33: 17687 | AH33: 130.02 | AI33: 8.61 | AK33: 13.375 | AL33: 4.6 | AM33: 10916.3 | AN33: 17688 | AO33: 101.22 | AP33: 8.61 | AR33: 13.375 | AS33: 4.6 | AT33: 10914.6 | AU33: 17687 | AV33: 72.42 | AW33: 8.61 | AY33: 13.375 | AZ33: 4.6 | BA33: 10772.9 | BB33: 18220 | BC33: 43.25 | BD33: 8.95 | BF33: 9.8 | BG33: 67539 | BH33: 66453 | BI33: 65367 | BJ33: 64280 | BK33: 63194 | BL33: 62108 | BM33: 61022 | BN33: 59936 | BO33: 58850 | BP33: 57764 | BQ33: 56677 | BR33: 55591 | BS33: 54505 | BT33: 53419 | BU33: 52333 | BV33: 51247 | BW33: 50161 | BX33: 49075 | BY33: 47989 | BZ33: 46903 | CA33: 45816 | CB33: 44730 | CC33: 43644 | CD33: 42558 | CE33: 41473 | CF33: 40387 | CG33: 39301 | CH33: 38215 | CI33: 37129 | CJ33: 36043 | CL33: 9.8 | CM33: 1.223 | CN33: 2.459 | CO33: 2.956 | CP33: 4.981 | CQ33: 7.559 | CR33: 9.43 | CS33: 10.658 | CT33: 11.254 | CU33: 11.194 | CW33: 9.8 | CX33: 1.23 | CY33: 2.473 | CZ33: 2.973 | DA33: 5.008 | DB33: 7.596 | DC33: 9.457 | DD33: 10.677 | DE33: 11.266 | DF33: 11.199
... B45: Bodega 3 (BW) | C45: 13348.7 | D45: 13081.8 | E45: 101.22 | F45: 0 | G45: 10.21 | H45: 63150 | J45: 4.8 | K45: 22566 | L45: 11522 | M45: 100.8 | N45: 2.48 | O45: 99.71 | P45: 19.91 | Q45: 561 | R45: 50.6 | S45: 0.772 | T45: 4934 | U45: 6130 | W45: 10.775 | X45: 7 | Y45: 8322.1 | Z45: 20807 | AA45: 158.7 | AB45: 7.41 | AD45: 10.975 | AE45: 7 | AF45: 9005.7 | AG45: 24624 | AH45: 130.02 | AI45: 7.48 | AK45: 10.975 | AL45: 7 | AM45: 9007 | AN45: 24629 | AO45: 101.22 | AP45: 7.48 | AR45: 10.975 | AS45: 7 | AT45: 9005.7 | AU45: 24624 | AV45: 72.42 | AW45: 7.48 | AY45: 10.975 | AZ45: 7 | BA45: 8738.4 | BB45: 25440 | BC45: 43.39 | BD45: 7.78 | BF45: 11 | BG45: 73139 | BH45: 71904 | BI45: 70669 | BJ45: 69433 | BK45: 68198 | BL45: 66963 | BM45: 65728 | BN45: 64492 | BO45: 63257 | BP45: 62022 | BQ45: 60786 | BR45: 59551 | BS45: 58315 | BT45: 57080 | BU45: 55845 | BV45: 54610 | BW45: 53374 | BX45: 52139 | BY45: 50904 | BZ45: 49669 | CA45: 48433 | CB45: 47198 | CC45: 45963 | CD45: 44727 | CE45: 43492 | CF45: 42257 | CG45: 41022 | CH45: 39787 | CI45: 38551 | CJ45: 37316 | CL45: 11 | CM45: 1.199 | CN45: 2.408 | CO45: 2.895 | CP45: 4.874 | CQ45: 7.204 | CR45: 9.077 | CS45: 10.349 | CT45: 10.98 | CU45: 11.04 | CW45: 11 | CX45: 1.204 | CY45: 2.42 | CZ45: 2.909 | DA45: 4.895 | DB45: 7.228 | DC45: 9.093 | DD45: 10.363 | DE45: 10.991 | DF45: 11.045
J46: 4.9 | K46: 23072 | L46: 12028 | M46: 100.78 | N46: 2.53 | O46: 99.64 | P46: 19.63 | Q46: 563.6 | R46: 50.7 | S46: 0.774 | T46: 4943 | U46: 6171 | W46: 10.575 | X46: 7.2 | Y46: 8159.9 | Z46: 21142 | AA46: 158.7 | AB46: 7.31 | AD46: 10.775 | AE46: 7.2 | AF46: 8834.6 | AG46: 25097 | AH46: 130.02 | AI46: 7.38 | AK46: 10.775 | AL46: 7.2 | AM46: 8835.9 | AN46: 25101 | AO46: 101.22 | AP46: 7.38 | AR46: 10.775 | AS46: 7.2 | AT46: 8834.7 | AU46: 25097 | AV46: 72.42 | AW46: 7.38 | AY46: 10.775 | AZ46: 7.2 | BA46: 8556 | BB46: 25852 | BC46: 43.41 | BD46: 7.68 | BF46: 11.1 | BG46: 73716 | BH46: 72468 | BI46: 71221 | BJ46: 69973 | BK46: 68725 | BL46: 67477 | BM46: 66229 | BN46: 64981 | BO46: 63734 | BP46: 62486 | BQ46: 61237 | BR46: 59989 | BS46: 58742 | BT46: 57494 | BU46: 56246 | BV46: 54998 | BW46: 53750 | BX46: 52502 | BY46: 51254 | BZ46: 50007 | CA46: 48758 | CB46: 47510 | CC46: 46262 | CD46: 45015 | CE46: 43767 | CF46: 42519 | CG46: 41271 | CH46: 40023 | CI46: 38775 | CJ46: 37528 | CL46: 11.1 | CM46: 1.197 | CN46: 2.406 | CO46: 2.892 | CP46: 4.869 | CQ46: 7.174 | CR46: 9.048 | CS46: 10.321 | CT46: 10.956 | CU46: 11.027 | CW46: 11.1 | CX46: 1.203 | CY46: 2.417 | CZ46: 2.906 | DA46: 4.889 | DB46: 7.197 | DC46: 9.063 | DD46: 10.335 | DE46: 10.968 | DF46: 11.032
B47: Total Water Ballast | C47: 31480.7 | D47: 30851.5 | J47: 5 | K47: 23579 | L47: 12535 | M47: 100.76 | N47: 2.59 | O47: 99.58 | P47: 19.36 | Q47: 566.2 | R47: 50.8 | S47: 0.775 | T47: 4952 | U47: 6212 | W47: 10.375 | X47: 7.4 | Y47: 7997.7 | Z47: 21456 | AA47: 158.7 | AB47: 7.21 | AD47: 10.575 | AE47: 7.4 | AF47: 8663.6 | AG47: 25555 | AH47: 130.02 | AI47: 7.28 | AK47: 10.575 | AL47: 7.4 | AM47: 8664.9 | AN47: 25560 | AO47: 101.22 | AP47: 7.28 | AR47: 10.575 | AS47: 7.4 | AT47: 8663.6 | AU47: 25555 | AV47: 72.42 | AW47: 7.28 | AY47: 10.575 | AZ47: 7.4 | BA47: 8373.6 | BB47: 26228 | BC47: 43.42 | BD47: 7.57 | BF47: 11.2 | BG47: 74313 | BH47: 73053 | BI47: 71792 | BJ47: 70532 | BK47: 69271 | BL47: 68011 | BM47: 66751 | BN47: 65490 | BO47: 64230 | BP47: 62969 | BQ47: 61708 | BR47: 60448 | BS47: 59187 | BT47: 57927 | BU47: 56666 | BV47: 55406 | BW47: 54145 | BX47: 52885 | BY47: 51624 | BZ47: 50364 | CA47: 49102 | CB47: 47842 | CC47: 46581 | CD47: 45321 | CE47: 44060 | CF47: 42800 | CG47: 41539 | CH47: 40279 | CI47: 39018 | CJ47: 37757 | CL47: 11.2 | CM47: 1.196 | CN47: 2.403 | CO47: 2.889 | CP47: 4.863 | CQ47: 7.145 | CR47: 9.019 | CS47: 10.293 | CT47: 10.933 | CU47: 11.014 | CW47: 11.2 | CX47: 1.202 | CY47: 2.415 | CZ47: 2.903 | DA47: 4.883 | DB47: 7.166 | DC47: 9.034 | DD47: 10.306 | DE47: 10.944 | DF47: 11.019
J48: 5.1 | K48: 24087 | L48: 13043 | M48: 100.73 | N48: 2.64 | O48: 99.5 | P48: 19.1 | Q48: 568.8 | R48: 50.9 | S48: 0.777 | T48: 4961 | U48: 6253 | W48: 10.175 | X48: 7.6 | Y48: 7835.5 | Z48: 21751 | AA48: 158.7 | AB48: 7.11 | AD48: 10.375 | AE48: 7.6 | AF48: 8492.6 | AG48: 26000 | AH48: 130.02 | AI48: 7.18 | AK48: 10.375 | AL48: 7.6 | AM48: 8493.8 | AN48: 26005 | AO48: 101.22 | AP48: 7.18 | AR48: 10.375 | AS48: 7.6 | AT48: 8492.6 | AU48: 26000 | AV48: 72.42 | AW48: 7.18 | AY48: 10.375 | AZ48: 7.6 | BA48: 8191.2 | BB48: 26570 | BC48: 43.44 | BD48: 7.47 | BF48: 11.3 | BG48: 74930 | BH48: 73657 | BI48: 72384 | BJ48: 71111 | BK48: 69837 | BL48: 68564 | BM48: 67290 | BN48: 66017 | BO48: 64743 | BP48: 63469 | BQ48: 62195 | BR48: 60921 | BS48: 59648 | BT48: 58374 | BU48: 57100 | BV48: 55833 | BW48: 54560 | BX48: 53287 | BY48: 52014 | BZ48: 50741 | CA48: 49468 | CB48: 48195 | CC48: 46921 | CD48: 45648 | CE48: 44375 | CF48: 43102 | CG48: 41829 | CH48: 40556 | CI48: 39283 | CJ48: 38010 | CL48: 11.3 | CM48: 1.195 | CN48: 2.401 | CO48: 2.887 | CP48: 4.858 | CQ48: 7.116 | CR48: 8.99 | CS48: 10.264 | CT48: 10.909 | CU48: 11.001 | CW48: 11.3 | CX48: 1.201 | CY48: 2.412 | CZ48: 2.9 | DA48: 4.877 | DB48: 7.136 | DC48: 9.004 | DD48: 10.277 | DE48: 10.92 | DF48: 11.006
J49: 5.2 | K49: 24596 | L49: 13552 | M49: 100.7 | N49: 2.69 | O49: 99.43 | P49: 18.85 | Q49: 571.4 | R49: 50.9 | S49: 0.777 | T49: 4969 | U49: 6294 | W49: 9.975 | X49: 7.8 | Y49: 7673.3 | Z49: 22029 | AA49: 158.69 | AB49: 7.01 | AD49: 10.175 | AE49: 7.8 | AF49: 8321.5 | AG49: 26430 | AH49: 130.02 | AI49: 7.08 | AK49: 10.175 | AL49: 7.8 | AM49: 8322.7 | AN49: 26435 | AO49: 101.22 | AP49: 7.08 | AR49: 10.175 | AS49: 7.8 | AT49: 8321.6 | AU49: 26430 | AV49: 72.42 | AW49: 7.08 | AY49: 10.175 | AZ49: 7.8 | BA49: 8008.8 | BB49: 26880 | BC49: 43.46 | BD49: 7.36 | BF49: 11.4 | BG49: 75569 | BH49: 74283 | BI49: 72997 | BJ49: 71712 | BK49: 70425 | BL49: 69139 | BM49: 67853 | BN49: 66567 | BO49: 65281 | BP49: 63995 | BQ49: 62709 | BR49: 61422 | BS49: 60136 | BT49: 58850 | BU49: 57564 | BV49: 56278 | BW49: 54992 | BX49: 53705 | BY49: 52419 | BZ49: 51133 | CA49: 49846 | CB49: 48560 | CC49: 47273 | CD49: 45987 | CE49: 44701 | CF49: 43414 | CG49: 42128 | CH49: 40842 | CI49: 39552 | CJ49: 38265 | CL49: 11.4 | CM49: 1.194 | CN49: 2.399 | CO49: 2.884 | CP49: 4.854 | CQ49: 7.087 | CR49: 8.961 | CS49: 10.236 | CT49: 10.885 | CU49: 10.988 | CW49: 11.4 | CX49: 1.2 | CY49: 2.41 | CZ49: 2.897 | DA49: 4.872 | DB49: 7.105 | DC49: 8.974 | DD49: 10.247 | DE49: 10.896 | DF49: 10.993
J50: 5.3 | K50: 25106 | L50: 14062 | M50: 100.68 | N50: 2.74 | O50: 99.35 | P50: 18.62 | Q50: 574 | R50: 51 | S50: 0.779 | T50: 4978 | U50: 6335 | W50: 9.775 | X50: 8 | Y50: 7511 | Z50: 22288 | AA50: 158.69 | AB50: 6.91 | AD50: 9.975 | AE50: 8 | AF50: 8150.5 | AG50: 26842 | AH50: 130.02 | AI50: 6.98 | AK50: 9.975 | AL50: 8 | AM50: 8151.6 | AN50: 26848 | AO50: 101.22 | AP50: 6.98 | AR50: 9.975 | AS50: 8 | AT50: 8150.5 | AU50: 26843 | AV50: 72.42 | AW50: 6.98 | AY50: 9.975 | AZ50: 8 | BA50: 7826.4 | BB50: 27155 | BC50: 43.48 | BD50: 7.25 | BF50: 11.5 | BG50: 76740 | BH50: 75446 | BI50: 74151 | BJ50: 72857 | BK50: 71563 | BL50: 69734 | BM50: 68435 | BN50: 67135 | BO50: 65835 | BP50: 64541 | BQ50: 63242 | BR50: 61943 | BS50: 60644 | BT50: 59345 | BU50: 58046 | BV50: 56747 | BW50: 55448 | BX50: 54149 | BY50: 52849 | BZ50: 51550 | CA50: 50250 | CB50: 48951 | CC50: 47652 | CD50: 46352 | CE50: 45053 | CF50: 43754 | CG50: 42455 | CH50: 41155 | CI50: 39856 | CJ50: 38556 | CL50: 11.5 | CM50: 1.193 | CN50: 2.397 | CO50: 2.882 | CP50: 4.849 | CQ50: 7.058 | CR50: 8.931 | CS50: 10.207 | CT50: 10.861 | CU50: 10.975 | CW50: 11.5 | CX50: 1.199 | CY50: 2.408 | CZ50: 2.895 | DA50: 4.867 | DB50: 7.075 | DC50: 8.944 | DD50: 10.218 | DE50: 10.872 | DF50: 10.98
J51: 5.4 | K51: 25617 | L51: 14573 | M51: 100.65 | N51: 2.79 | O51: 99.27 | P51: 18.4 | Q51: 576.7 | R51: 51.1 | S51: 0.78 | T51: 4987 | U51: 6377 | W51: 9.575 | X51: 8.2 | Y51: 7348.8 | Z51: 22528 | AA51: 158.69 | AB51: 6.81 | AD51: 9.775 | AE51: 8.2 | AF51: 7979.4 | AG51: 27234 | AH51: 130.02 | AI51: 6.87 | AK51: 9.775 | AL51: 8.2 | AM51: 7980.6 | AN51: 27239 | AO51: 101.22 | AP51: 6.87 | AR51: 9.775 | AS51: 8.2 | AT51: 7979.5 | AU51: 27234 | AV51: 72.42 | AW51: 6.87 | AY51: 9.775 | AZ51: 8.2 | BA51: 7644 | BB51: 27398 | BC51: 43.5 | BD51: 7.15 | BF51: 11.6 | BG51: 77352 | BH51: 76045 | BI51: 74738 | BJ51: 73432 | BK51: 72125 | BL51: 70818 | BM51: 69511 | BN51: 68204 | BO51: 66898 | BP51: 65591 | BQ51: 63759 | BR51: 62447 | BS51: 61135 | BT51: 59823 | BU51: 58511 | BV51: 57199 | BW51: 55887 | BX51: 54576 | BY51: 53263 | BZ51: 51952 | CA51: 50639 | CB51: 49327 | CC51: 48015 | CD51: 46703 | CE51: 45391 | CF51: 44080 | CG51: 42768 | CH51: 41456 | CI51: 40144 | CJ51: 38832 | CL51: 11.6 | CM51: 1.193 | CN51: 2.396 | CO51: 2.88 | CP51: 4.846 | CQ51: 7.03 | CR51: 8.901 | CS51: 10.177 | CT51: 10.837 | CU51: 10.961 | CW51: 11.6 | CX51: 1.198 | CY51: 2.406 | CZ51: 2.892 | DA51: 4.863 | DB51: 7.046 | DC51: 8.913 | DD51: 10.188 | DE51: 10.848 | DF51: 10.967
B52: Heavy Fuel Oil | C52: Vol 100% | D52: Vol 98% | E52: LCG | F52: TCG | G52: VCG | H52: FSM (m4) | J52: 5.5 | K52: 26129 | L52: 15085 | M52: 100.62 | N52: 2.85 | O52: 99.19 | P52: 18.18 | Q52: 579.4 | R52: 51.2 | S52: 0.781 | T52: 4996 | U52: 6418 | W52: 9.375 | X52: 8.4 | Y52: 7186.6 | Z52: 22749 | AA52: 158.69 | AB52: 6.71 | AD52: 9.575 | AE52: 8.4 | AF52: 7808.4 | AG52: 27604 | AH52: 130.02 | AI52: 6.77 | AK52: 9.575 | AL52: 8.4 | AM52: 7809.5 | AN52: 27610 | AO52: 101.22 | AP52: 6.77 | AR52: 9.575 | AS52: 8.4 | AT52: 7808.4 | AU52: 27604 | AV52: 72.42 | AW52: 6.77 | AY52: 9.575 | AZ52: 8.4 | BA52: 7461.6 | BB52: 27609 | BC52: 43.52 | BD52: 7.04 | BF52: 11.7 | BG52: 77975 | BH52: 76656 | BI52: 75336 | BJ52: 74017 | BK52: 72698 | BL52: 71378 | BM52: 70059 | BN52: 68740 | BO52: 67421 | BP52: 66101 | BQ52: 64262 | BR52: 62936 | BS52: 61610 | BT52: 60284 | BU52: 58958 | BV52: 57632 | BW52: 56306 | BX52: 54980 | BY52: 53654 | BZ52: 52328 | CA52: 51001 | CB52: 49675 | CC52: 48349 | CD52: 47023 | CE52: 45697 | CF52: 44371 | CG52: 43045 | CH52: 41719 | CI52: 40393 | CJ52: 39067 | CL52: 11.7 | CM52: 1.192 | CN52: 2.394 | CO52: 2.878 | CP52: 4.842 | CQ52: 7.003 | CR52: 8.871 | CS52: 10.147 | CT52: 10.812 | CU52: 10.948 | CW52: 11.7 | CX52: 1.197 | CY52: 2.404 | CZ52: 2.89 | DA52: 4.859 | DB52: 7.018 | DC52: 8.882 | DD52: 10.157 | DE52: 10.823 | DF52: 10.954
B53: HFO Deep P 1 | C53: 433.9 | D53: 425.3 | E53: 23.89 | F53: -9.91 | G53: 12.56 | H53: 355 | J53: 5.6 | K53: 26641 | L53: 15597 | M53: 100.59 | N53: 2.9 | O53: 99.11 | P53: 17.98 | Q53: 582.1 | R53: 51.3 | S53: 0.782 | T53: 5004 | U53: 6459 | W53: 9.175 | X53: 8.6 | Y53: 7024.4 | Z53: 22954 | AA53: 158.69 | AB53: 6.6 | AD53: 9.375 | AE53: 8.6 | AF53: 7637.4 | AG53: 27954 | AH53: 130.01 | AI53: 6.67 | AK53: 9.375 | AL53: 8.6 | AM53: 7638.4 | AN53: 27960 | AO53: 101.22 | AP53: 6.67 | AR53: 9.375 | AS53: 8.6 | AT53: 7637.4 | AU53: 27954 | AV53: 72.42 | AW53: 6.67 | AY53: 9.375 | AZ53: 8.6 | BA53: 7279.2 | BB53: 27790 | BC53: 43.54 | BD53: 6.94 | BF53: 11.8 | BG53: 78605 | BH53: 77273 | BI53: 75941 | BJ53: 74610 | BK53: 73278 | BL53: 71946 | BM53: 70614 | BN53: 69282 | BO53: 67950 | BP53: 66619 | BQ53: 65286 | BR53: 63954 | BS53: 62622 | BT53: 61290 | BU53: 59457 | BV53: 58118 | BW53: 56780 | BX53: 55441 | BY53: 54102 | BZ53: 52763 | CA53: 51424 | CB53: 50086 | CC53: 48747 | CD53: 47408 | CE53: 46069 | CF53: 44730 | CG53: 43391 | CH53: 42053 | CI53: 40714 | CJ53: 39375 | CL53: 11.8 | CM53: 1.191 | CN53: 2.393 | CO53: 2.877 | CP53: 4.838 | CQ53: 6.976 | CR53: 8.84 | CS53: 10.117 | CT53: 10.788 | CU53: 10.935 | CW53: 11.8 | CX53: 1.196 | CY53: 2.403 | CZ53: 2.889 | DA53: 4.854 | DB53: 6.99 | DC53: 8.85 | DD53: 10.127 | DE53: 10.799 | DF53: 10.941
B54: HFO Deep S 1 | C54: 343.4 | D54: 336.5 | E54: 24.07 | F54: 10.62 | G54: 12.31 | H54: 211 | J54: 5.7 | K54: 27155 | L54: 16111 | M54: 100.56 | N54: 2.95 | O54: 99.02 | P54: 17.78 | Q54: 584.8 | R54: 51.4 | S54: 0.783 | T54: 5013 | U54: 6500 | W54: 8.975 | X54: 8.8 | Y54: 6862.2 | Z54: 23143 | AA54: 158.69 | AB54: 6.5 | AD54: 9.175 | AE54: 8.8 | AF54: 7466.3 | AG54: 28285 | AH54: 130.01 | AI54: 6.57 | AK54: 9.175 | AL54: 8.8 | AM54: 7467.3 | AN54: 28291 | AO54: 101.22 | AP54: 6.57 | AR54: 9.175 | AS54: 8.8 | AT54: 7466.4 | AU54: 28285 | AV54: 72.42 | AW54: 6.57 | AY54: 9.175 | AZ54: 8.8 | BA54: 7096.9 | BB54: 27946 | BC54: 43.56 | BD54: 6.83 | BF54: 11.9 | BG54: 79239 | BH54: 77895 | BI54: 76550 | BJ54: 75206 | BK54: 73861 | BL54: 72517 | BM54: 71173 | BN54: 69828 | BO54: 68484 | BP54: 67140 | BQ54: 65795 | BR54: 64450 | BS54: 63106 | BT54: 61761 | BU54: 60417 | BV54: 59073 | BW54: 57728 | BX54: 56384 | BY54: 55040 | BZ54: 53223 | CA54: 51871 | CB54: 50520 | CC54: 49169 | CD54: 47820 | CE54: 46473 | CF54: 45127 | CG54: 43781 | CH54: 42435 | CI54: 41090 | CJ54: 39744 | CL54: 11.9 | CM54: 1.191 | CN54: 2.392 | CO54: 2.876 | CP54: 4.834 | CQ54: 6.95 | CR54: 8.809 | CS54: 10.087 | CT54: 10.764 | CU54: 10.922 | CW54: 11.9 | CX54: 1.196 | CY54: 2.402 | CZ54: 2.887 | DA54: 4.849 | DB54: 6.963 | DC54: 8.819 | DD54: 10.096 | DE54: 10.774 | DF54: 10.928
B55: HFO Deep P 2 | C55: 533.2 | D55: 522.5 | E55: 17.92 | F55: -9.46 | G55: 12.38 | H55: 592 | J55: 5.8 | K55: 27669 | L55: 16625 | M55: 100.53 | N55: 3 | O55: 98.92 | P55: 17.59 | Q55: 587.6 | R55: 51.5 | S55: 0.784 | T55: 5022 | U55: 6542 | W55: 8.775 | X55: 9 | Y55: 6700 | Z55: 23318 | AA55: 158.69 | AB55: 6.4 | AD55: 8.975 | AE55: 9 | AF55: 7295.3 | AG55: 28596 | AH55: 130.01 | AI55: 6.47 | AK55: 8.975 | AL55: 9 | AM55: 7296.3 | AN55: 28602 | AO55: 101.22 | AP55: 6.47 | AR55: 8.975 | AS55: 9 | AT55: 7295.3 | AU55: 28596 | AV55: 72.42 | AW55: 6.47 | AY55: 8.975 | AZ55: 9 | BA55: 6914.5 | BB55: 28078 | BC55: 43.58 | BD55: 6.72 | BF55: 12 | BG55: 79873 | BH55: 78516 | BI55: 77160 | BJ55: 75803 | BK55: 74446 | BL55: 73089 | BM55: 71732 | BN55: 70375 | BO55: 69018 | BP55: 67661 | BQ55: 66303 | BR55: 64946 | BS55: 63589 | BT55: 62233 | BU55: 60876 | BV55: 59519 | BW55: 58162 | BX55: 56805 | BY55: 55050 | BZ55: 53691 | CA55: 52331 | CB55: 50972 | CC55: 49613 | CD55: 48254 | CE55: 46895 | CF55: 45537 | CG55: 44178 | CH55: 42820 | CI55: 41461 | CJ55: 40103 | CL55: 12 | CM55: 1.19 | CN55: 2.391 | CO55: 2.875 | CP55: 4.829 | CQ55: 6.924 | CR55: 8.778 | CS55: 10.056 | CT55: 10.739 | CU55: 10.909 | CW55: 12 | CX55: 1.195 | CY55: 2.401 | CZ55: 2.886 | DA55: 4.844 | DB55: 6.937 | DC55: 8.786 | DD55: 10.065 | DE55: 10.749 | DF55: 10.915
B56: HFO Deep S 2 | C56: 474.2 | D56: 464.7 | E56: 17.47 | F56: 9.93 | G56: 12.39 | H56: 494 | J56: 5.9 | K56: 28184 | L56: 17140 | M56: 100.5 | N56: 3.05 | O56: 98.83 | P56: 17.41 | Q56: 590.4 | R56: 51.6 | S56: 0.785 | T56: 5030 | U56: 6583 | W56: 8.575 | X56: 9.2 | Y56: 6537.8 | Z56: 23480 | AA56: 158.69 | AB56: 6.3 | AD56: 8.775 | AE56: 9.2 | AF56: 7124.3 | AG56: 28886 | AH56: 130.01 | AI56: 6.37 | AK56: 8.775 | AL56: 9.2 | AM56: 7125.2 | AN56: 28892 | AO56: 101.22 | AP56: 6.37 | AR56: 8.775 | AS56: 9.2 | AT56: 7124.3 | AU56: 28886 | AV56: 72.42 | AW56: 6.37 | AY56: 8.775 | AZ56: 9.2 | BA56: 6732.2 | BB56: 28185 | BC56: 43.61 | BD56: 6.61 | BF56: 12.1 | BG56: 80507 | BH56: 79138 | BI56: 77768 | BJ56: 76399 | BK56: 75029 | BL56: 73660 | BM56: 72004 | BN56: 70629 | BO56: 69254 | BP56: 67880 | BQ56: 66504 | BR56: 65130 | BS56: 63755 | BT56: 62382 | BU56: 61010 | BV56: 59637 | BW56: 58264 | BX56: 56892 | BY56: 55519 | BZ56: 54147 | CA56: 52774 | CB56: 51401 | CC56: 50029 | CD56: 48656 | CE56: 47284 | CF56: 45912 | CG56: 44539 | CH56: 43167 | CI56: 41795 | CJ56: 40423 | CL56: 12.1 | CM56: 1.19 | CN56: 2.391 | CO56: 2.874 | CP56: 4.824 | CQ56: 6.899 | CR56: 8.746 | CS56: 10.025 | CT56: 10.714 | CU56: 10.896 | CW56: 12.1 | CX56: 1.195 | CY56: 2.4 | CZ56: 2.884 | DA56: 4.838 | DB56: 6.911 | DC56: 8.754 | DD56: 10.033 | DE56: 10.724 | DF56: 10.902
B57: HFO Service Tk 1 | C57: 45.2 | D57: 44.3 | E57: 22.4 | F57: 7.19 | G57: 13.5 | H57: 4 | J57: 6 | K57: 28700 | L57: 17656 | M57: 100.47 | N57: 3.11 | O57: 98.73 | P57: 17.24 | Q57: 593.2 | R57: 51.7 | S57: 0.786 | T57: 5039 | U57: 6624 | W57: 8.375 | X57: 9.4 | Y57: 6375.6 | Z57: 23631 | AA57: 158.69 | AB57: 6.2 | AD57: 8.575 | AE57: 9.4 | AF57: 6953.2 | AG57: 29160 | AH57: 130.01 | AI57: 6.27 | AK57: 8.575 | AL57: 9.4 | AM57: 6954.1 | AN57: 29166 | AO57: 101.22 | AP57: 6.27 | AR57: 8.575 | AS57: 9.4 | AT57: 6953.3 | AU57: 29160 | AV57: 72.42 | AW57: 6.27 | AY57: 8.575 | AZ57: 9.4 | BA57: 6550 | BB57: 28265 | BC57: 43.63 | BD57: 6.5 | BF57: 12.2 | BG57: 81140 | BH57: 79758 | BI57: 78376 | BJ57: 76994 | BK57: 75612 | BL57: 74011 | BM57: 72623 | BN57: 71235 | BO57: 69848 | BP57: 68460 | BQ57: 67072 | BR57: 65685 | BS57: 64299 | BT57: 62914 | BU57: 61528 | BV57: 60142 | BW57: 58756 | BX57: 57370 | BY57: 55984 | BZ57: 54598 | CA57: 53211 | CB57: 51825 | CC57: 50439 | CD57: 49053 | CE57: 47667 | CF57: 46281 | CG57: 44895 | CH57: 43509 | CI57: 42123 | CJ57: 40737 | CL57: 12.2 | CM57: 1.19 | CN57: 2.39 | CO57: 2.873 | CP57: 4.818 | CQ57: 6.875 | CR57: 8.714 | CS57: 9.994 | CT57: 10.689 | CU57: 10.883 | CW57: 12.2 | CX57: 1.194 | CY57: 2.399 | CZ57: 2.884 | DA57: 4.831 | DB57: 6.885 | DC57: 8.722 | DD57: 10.002 | DE57: 10.698 | DF57: 10.889
B58: HFO Service Tk 2 | C58: 45.2 | D58: 44.3 | E58: 20.8 | F58: 7.19 | G58: 13.5 | H58: 4 | J58: 6.1 | K58: 29217 | L58: 18173 | M58: 100.44 | N58: 3.16 | O58: 98.63 | P58: 17.08 | Q58: 596 | R58: 51.7 | S58: 0.788 | T58: 5048 | U58: 6666 | W58: 8.175 | X58: 9.6 | Y58: 6213.4 | Z58: 23766 | AA58: 158.69 | AB58: 6.1 | AD58: 8.375 | AE58: 9.6 | AF58: 6782.2 | AG58: 29417 | AH58: 130.01 | AI58: 6.16 | AK58: 8.375 | AL58: 9.6 | AM58: 6783 | AN58: 29423 | AO58: 101.22 | AP58: 6.16 | AR58: 8.375 | AS58: 9.6 | AT58: 6782.2 | AU58: 29417 | AV58: 72.42 | AW58: 6.16 | AY58: 8.375 | AZ58: 9.6 | BA58: 6367.8 | BB58: 28315 | BC58: 43.66 | BD58: 6.4 | BF58: 12.3 | BG58: 81911 | BH58: 80510 | BI58: 79108 | BJ58: 77707 | BK58: 76306 | BL58: 74904 | BM58: 73503 | BN58: 72101 | BO58: 70700 | BP58: 69298 | BQ58: 67897 | BR58: 66496 | BS58: 65100 | BT58: 63703 | BU58: 62046 | BV58: 60646 | BW58: 59247 | BX58: 57848 | BY58: 56448 | BZ58: 55048 | CA58: 53648 | CB58: 52248 | CC58: 50849 | CD58: 49449 | CE58: 48049 | CF58: 46649 | CG58: 45250 | CH58: 43850 | CI58: 42450 | CJ58: 41050 | CL58: 12.3 | CM58: 1.19 | CN58: 2.39 | CO58: 2.873 | CP58: 4.811 | CQ58: 6.851 | CR58: 8.683 | CS58: 9.962 | CT58: 10.664 | CU58: 10.869 | CW58: 12.3 | CX58: 1.194 | CY58: 2.398 | CZ58: 2.883 | DA58: 4.823 | DB58: 6.86 | DC58: 8.689 | DD58: 9.97 | DE58: 10.673 | DF58: 10.876
...

Sheet Navegación
E7: Origen (A) | L7: Destino (B)
E8: Puerto: | F8: =Interfaz!F129 -> Anchorage | L8: Puerto: | M8: =Interfaz!K129 -> Auckland | Q8: Ver Cuentas
E9: =IFERROR(LOOKUP(F8,AC12:AC119,AG12:AG119),"") -> 61.233333 | F9: =IF(E9>0,"N","S") -> N | G9: =IFERROR(LOOKUP(F8,AC12:AC119,AK12:AK119),"") -> -149.88333 | H9: =IF(G9>0,"E","W") -> W | L9: =IFERROR(LOOKUP(M8,AC12:AC119,AG12:AG119),"") -> -36.833333 | M9: =IF(L9>0,"N","S") -> S | N9: =IFERROR(LOOKUP(M8,AC12:AC119,AK12:AK119),"") -> 174.78333 | O9: =IF(N9>0,"E","W") -> E
E10: º | F10: ′ | G10: " | H10: N/S | L10: º | M10: ′ | N10: " | O10: N/S
E11: {=Interfaz!E132:G132} -> 0 | F11: 0 | G11: 0 | H11: =Interfaz!H132 -> N | I11: =IF(H11="N",E11+F11/60+G11/(60*60),IF(H11="S",-E11-F11/60-G11/(60*60))) -> 0 | L11: {=Interfaz!J132:L132} -> 0 | M11: 0 | N11: 0 | O11: =Interfaz!M132 -> N | P11: =IF(O11="N",L11+M11/60+N11/(60*60),IF(O11="S",-L11-M11/60-N11/(60*60))) -> 0 | S11: ϕa B | T11: =LN(TAN(RADIANS(45+M14/2)))*180/PI() -> -39.668714 | U11: "+90º" | V11: =T11+90 -> 50.331286 | W11: λ B | X11: =O14 -> 174.78333 | Y11: "+180º" | Z11: =X11+180 -> 354.78333 | AC11: Nombre | AD11: Lat_Grados | AE11: Lat_Min | AF11: Lat_Seg | AH11: Lon_Grados | AI11: Lon_Min | AJ11: Lon_Seg | AL11: Otro
E12: º | F12: ′ | G12: " | H12: E/W | L12: º | M12: ′ | N12: " | O12: E/W | S12: ϕa A | T12: =LN(TAN(RADIANS(45+F14/2)))*180/PI() -> 77.970155 | U12: "+90º" | V12: =T12+90 -> 167.97015 | W12: λ A | X12: =H14 -> -149.88333 | Y12: "+180º" | Z12: =X12+180 -> 30.116667 | AC12: Aarhus | AD12: 56 | AE12: 9 | AF12: 0 | AG12: =IF(Tabla6[[#This Row],[Columna1]]>0,Tabla6[[#This Row],[Columna1]]+Tabla6[[#This Row],[Columna2]]/60+Tabla6[[#This Row],[Columna3]]/(60*60),IF(Tabla6[[#This Row],[Columna1]]<0,Tabla6[[#This Row],[Columna1]]-Tabla6[[#This Row],[Columna2]]/60-Tabla6[[#This Row],[Columna3]]/(60*60),IF(Tabla6[[#This Row],[Columna1]]=0,IF(Tabla6[[#This Row],[Columna2]]>0,0+Tabla6[[#This Row],[Columna2]]/60+Tabla6[[#This Row],[Columna3]]/(60*60),IF(Tabla6[[#This Row],[Columna2]]<0,0-Tabla6[[#This Row],[Columna2]]/60-Tabla6[[#This Row],[Columna3]]/(60*60),"Error"))))) -> 56.15 | AH12: 10 | AI12: 13 | AJ12: 0 | AK12: =IF(Tabla6[[#This Row],[Columna5]]>0,Tabla6[[#This Row],[Columna5]]+Tabla6[[#This Row],[Columna6]]/60+Tabla6[[#This Row],[Columna7]]/(60*60),IF(Tabla6[[#This Row],[Columna5]]<0,Tabla6[[#This Row],[Columna5]]-Tabla6[[#This Row],[Columna6]]/60-Tabla6[[#This Row],[Columna7]]/(60*60),IF(Tabla6[[#This Row],[Columna5]]=0,IF(Tabla6[[#This Row],[Columna6]]>0,0+Tabla6[[#This Row],[Columna6]]/60+Tabla6[[#This Row],[Columna7]]/(60*60),IF(Tabla6[[#This Row],[Columna6]]<0,0-Tabla6[[#This Row],[Columna6]]/60-Tabla6[[#This Row],[Columna7]]/(60*60),"Error"))))) -> 10.216667 | AL12: Aarhus
